<?xml version="1.0"?>
<robot xmlns:xacro="http://www.ros.org/wiki/xacro" name="navvis">

<xacro:include filename="$(find gazebo_plugins)/test/multi_robot_scenario/xacro/laser/hokuyo.xacro" />

<xacro:include filename="$(find velodyne_description)/urdf/VLP-16.urdf.xacro" />

<xacro:VLP-16 parent="base" name="laser_horiz" topic="laser_horiz/packets" hz="10" samples="440" gpu="false">
  <origin xyz="0.2325416305773505 -0.001380069427607134 1.920122926231907" rpy="-0.0012068 0.114646 -0.0015308" />
</xacro:VLP-16>

<xacro:laser name="laser_vert_bottom" parent="base" xyz="0.3157894464801903 -0.002068548615034871 0.5099999434959285" rpy="3.1354753 -1.3045001 0.0024658" meshes="package://gazebo_plugins/test/multi_robot_scenario/meshes/laser" />

<xacro:laser name="laser_vert_top_right" parent="base" xyz="0.2978 -0.1450 1.8451" rpy="-1.1760 0.6313 -1.9377" meshes="package://gazebo_plugins/test/multi_robot_scenario/meshes/laser" />

<xacro:laser name="laser_vert_top_left" parent="base" xyz="0.2997 0.01531 1.8443" rpy="1.1780 0.6198 1.9560" meshes="package://gazebo_plugins/test/multi_robot_scenario/meshes/laser" />

  <link name="base">
    <visual>
      <!-- Shift the box up half its height. !-->
      <origin xyz="0.0 0.0 0.96" rpy="0.0 0.0 0.0" />
      <geometry>
        <box size="0.45 0.78 1.92" />
      </geometry>
    </visual>
    <collision>
    <!--Shift the box up half its height. !-->
      <origin xyz="0.0 0.0 0.96" rpy="0.0 0.0 0.0" />
      <geometry>
        <box size="0.45 0.78 1.92" />
      </geometry>
    </collision>
  </link>

<!-- XACRO Macro definition block to add around the wheel link and joint !-->
 <xacro:macro name="wheel" params="side reflect">
	  <link name="wheel_${side}">
	    <visual>
	       <origin xyz="0.0 0.0 0.0" rpy="0.0 0.0 0.0" />
	      <geometry>
		<cylinder length="0.05" radius="0.2" />
	      </geometry>
	    </visual>
	    <collision>
	       <origin xyz="0.0 0.0 0.0" rpy="0.0 0.0 0.0" />
	      <geometry>
		<cylinder length="0.05" radius="0.2" />
	      </geometry>
	    </collision>
	  </link>

	  <joint name="base_wheel_${side}_joint" type="continuous">
	    <parent link="base" />
	    <child link="wheel_${side}" />
	    <origin xyz="-0.10 ${reflect * 0.4} 0.0" rpy="-1.57079632679 0.0 0.0" />

            <axis xyz="0.0 0.0 1.0" />
	    <limit effort = "10" velocity = "10" />
	  </joint>
 </xacro:macro>

<!-- Call the XACRO Macro. RIGHT and LEFT wheels !-->
<xacro:wheel side="left" reflect="1" />
<xacro:wheel side="right" reflect="-1" />

  <link name="center_wheel">
    <visual>
       <origin xyz="0.0 0.0 0.0" rpy="0.0 0.0 0.0" />
      <geometry>
        <cylinder length="0.05" radius="0.15" />
      </geometry>
    </visual>
    <collision>
       <origin xyz="0.0 0.0 0.0" rpy="0.0 0.0 0.0" />
      <geometry>
        <cylinder length="0.05" radius="0.15" />
      </geometry>
    </collision>
  </link>

  <joint name="base_center_wheel_joint" type="continuous">
    <parent link="base" />
    <child link="center_wheel" />
    <origin xyz="0.10 0.0 0.0" rpy="1.57079632679 0.0 0.0" />

    <axis xyz="0 0.0 1.0" />
    <limit effort = "10" velocity = "10" />
  </joint>



</robot>
